Workbook

Sheet AnalisisMTG
E1: Value
E2: Monday | H2: Tuesday | K2: Wednesday | N2: Thursday | Q2: Friday | T2: Saturday | W2: Sunday | Z2: Lunes | AA2: Martes | AB2: Miércoles | AC2: Jueves | AD2: Viernes | AE2: Sábado | AF2: Domingo | AG2: Lunes | AH2: Martes | AI2: Miércoles | AJ2: Jueves | AK2: Viernes | AL2: Sábado | AM2: Domingo | AS2: Sonometros
B3: Mes | C3: Tag | E3: dia | F3: tarde | G3: noche | H3: dia | I3: tarde | J3: noche | K3: dia | L3: tarde | M3: noche | N3: dia | O3: tarde | P3: noche | Q3: dia | R3: tarde | S3: noche | T3: dia | U3: tarde | V3: noche | W3: dia | X3: tarde | Y3: noche | Z3: Ld-Ln | AA3: Ld-Ln | AB3: Ld-Ln | AC3: Ld-Ln | AD3: Ld-Ln | AE3: Ld-Ln | AF3: Ld-Ln | AG3: Ld-Le | AH3: Ld-Le | AI3: Ld-Le | AJ3: Ld-Le | AK3: Ld-Le | AL3: Ld-Le | AM3: Ld-Le | AN3: Sonómetros con Perfil noche | AO3: Sonómetros con Perfil tarde | AS3: Perfil Tarde | AV3: Total Red
A4: 187 | B4: enero | C4: BI-RUI-001LD | D4: Rgez. Arias | E4: 62.658795 | F4: 62.476106 | G4: 60.494662 | H4: 62.935587 | I4: 60.60414 | J4: 62.766541 | K4: 66.611396 | L4: 62.119917 | M4: 67.73573 | N4: 62.907461 | O4: 62.004881 | P4: 61.88153 | Q4: 66.467463 | R4: 63.06384 | S4: 68.529278 | T4: 62.893726 | U4: 62.271837 | V4: 70.64724 | W4: 61.994614 | X4: 61.622052 | Y4: 69.121966 | Z4: =E4-G4 -> 2.164133 | AA4: =H4-J4 -> 0.16904626 | AB4: =K4-M4 -> -1.1243341 | AC4: =N4-P4 -> 1.025931 | AD4: =Q4-S4 -> -2.0618157 | AE4: =T4-V4 -> -7.7535144 | AF4: =W4-Y4 -> -7.1273529 | AG4: =E4-F4 -> 0.18268929 | AH4: =F4-G4 -> 1.9814437 | AI4: =K4-L4 -> 4.4914786 | AJ4: =N4-O4 -> 0.9025799 | AK4: =Q4-R4 -> 3.403623 | AL4: =T4-U4 -> 0.62188902 | AM4: =W4-X4 -> 0.37256116 | AN4: =IF(AF4<-2,C4,IF(AE4<-2,C4,"")) -> BI-RUI-001LD | AO4: =IF(AM4<-2,C4,IF(AL4<-2,C4,"")) | AP4: {=_xlfn.UNIQUE(AN:AN)} -> 0
A5: 250 | B5: febrero | C5: BI-RUI-001LD | E5: 63.347523 | F5: 59.768522 | G5: 59.805261 | H5: 64.505799 | I5: 62.675691 | J5: 60.824725 | K5: 63.481903 | L5: 60.467503 | M5: 62.059144 | N5: 63.733194 | O5: 61.346972 | P5: 61.365897 | Q5: 66.231968 | R5: 63.272475 | S5: 68.484382 | T5: 63.21594 | U5: 60.59231 | V5: 70.470423 | W5: 62.77499 | X5: 58.723377 | Y5: 67.885564 | Z5: =E5-G5 -> 3.542262 | AA5: =H5-J5 -> 3.6810739 | AB5: =K5-M5 -> 1.4227596 | AC5: =N5-P5 -> 2.3672965 | AD5: =Q5-S5 -> -2.2524137 | AE5: =T5-V5 -> -7.254483 | AF5: =W5-Y5 -> -5.1105732 | AG5: =E5-F5 -> 3.5790011 | AH5: =F5-G5 -> -0.036739171 | AI5: =K5-L5 -> 3.0143999 | AJ5: =N5-O5 -> 2.3862219 | AK5: =Q5-R5 -> 2.9594932 | AL5: =T5-U5 -> 2.6236301 | AM5: =W5-X5 -> 4.051613 | AN5: =IF(AF5<-2,C5,IF(AE5<-2,C5,"")) -> BI-RUI-001LD | AO5: =IF(AM5<-2,C5,IF(AL5<-2,C5,"")) | AP5: Sonómetros con Perfil noche | AQ5: 44 sonómetros | AS5: {=_xlfn.UNIQUE(AO4:AO750)} | AV5: {=_xlfn.UNIQUE(C4:C750)} -> BI-RUI-001LD
A6: 438 | B6: marzo | C6: BI-RUI-001LD | E6: 64.627038 | F6: 60.730735 | G6: 60.852731 | H6: 64.157622 | I6: 61.184763 | J6: 61.734293 | K6: 65.110056 | L6: 60.831295 | M6: 60.881975 | N6: 63.813905 | O6: 61.203351 | P6: 61.576753 | Q6: 66.334472 | R6: 62.720985 | S6: 69.215179 | T6: 62.326535 | U6: 62.392355 | V6: 70.790639 | W6: 61.773812 | X6: 63.953514 | Y6: 69.494636 | Z6: =E6-G6 -> 3.774307 | AA6: =H6-J6 -> 2.4233286 | AB6: =K6-M6 -> 4.2280804 | AC6: =N6-P6 -> 2.2371518 | AD6: =Q6-S6 -> -2.880707 | AE6: =T6-V6 -> -8.4641045 | AF6: =W6-Y6 -> -7.7208234 | AG6: =E6-F6 -> 3.8963025 | AH6: =F6-G6 -> -0.12199552 | AI6: =K6-L6 -> 4.2787609 | AJ6: =N6-O6 -> 2.6105535 | AK6: =Q6-R6 -> 3.6134868 | AL6: =T6-U6 -> -0.065820134 | AM6: =W6-X6 -> -2.1797019 | AN6: =IF(AF6<-2,C6,IF(AE6<-2,C6,"")) -> BI-RUI-001LD | AO6: =IF(AM6<-2,C6,IF(AL6<-2,C6,"")) -> BI-RUI-001LD | AP6: BI-RUI-001LD | AS6: BI-RUI-001LD | AV6: BI-RUI-004LD
A7: 0 | B7: abril | C7: BI-RUI-001LD | E7: 61.580151 | F7: 60.443165 | G7: 59.517598 | H7: 63.287053 | I7: 70.515742 | J7: 63.670796 | K7: 63.609378 | L7: 62.114813 | M7: 68.190563 | N7: 61.978456 | O7: 63.970992 | P7: 62.901147 | Q7: 64.228229 | R7: 61.16625 | S7: 69.298418 | T7: 63.132935 | U7: 63.961765 | V7: 70.498133 | W7: 63.17597 | X7: 59.126623 | Y7: 68.685567 | Z7: =E7-G7 -> 2.0625525 | AA7: =H7-J7 -> -0.38374373 | AB7: =K7-M7 -> -4.5811849 | AC7: =N7-P7 -> -0.92269058 | AD7: =Q7-S7 -> -5.0701892 | AE7: =T7-V7 -> -7.3651975 | AF7: =W7-Y7 -> -5.5095966 | AG7: =E7-F7 -> 1.1369857 | AH7: =F7-G7 -> 0.92556677 | AI7: =K7-L7 -> 1.4945659 | AJ7: =N7-O7 -> -1.9925351 | AK7: =Q7-R7 -> 3.0619791 | AL7: =T7-U7 -> -0.82883031 | AM7: =W7-X7 -> 4.049347 | AN7: =IF(AF7<-2,C7,IF(AE7<-2,C7,"")) -> BI-RUI-001LD | AO7: =IF(AM7<-2,C7,IF(AL7<-2,C7,"")) | AS7: BI-RUI-004LD | AV7: BI-RUI-005LD
A8: 501 | B8: mayo | C8: BI-RUI-001LD | E8: 63.523597 | F8: 59.978862 | G8: 63.361538 | H8: 62.902213 | I8: 60.726175 | J8: 59.719009 | K8: 62.282605 | L8: 61.122283 | M8: 60.654664 | N8: 62.659114 | O8: 64.861398 | P8: 61.488208 | Q8: 66.479412 | R8: 62.672438 | S8: 70.321195 | T8: 63.180426 | U8: 62.738659 | V8: 70.650322 | W8: 62.779969 | X8: 60.669288 | Y8: 69.077105 | Z8: =E8-G8 -> 0.16205927 | AA8: =H8-J8 -> 3.1832043 | AB8: =K8-M8 -> 1.6279401 | AC8: =N8-P8 -> 1.1709056 | AD8: =Q8-S8 -> -3.8417837 | AE8: =T8-V8 -> -7.4698963 | AF8: =W8-Y8 -> -6.2971355 | AG8: =E8-F8 -> 3.5447354 | AH8: =F8-G8 -> -3.3826762 | AI8: =K8-L8 -> 1.160322 | AJ8: =N8-O8 -> -2.2022843 | AK8: =Q8-R8 -> 3.8069734 | AL8: =T8-U8 -> 0.4417673 | AM8: =W8-X8 -> 2.1106813 | AN8: =IF(AF8<-2,C8,IF(AE8<-2,C8,"")) -> BI-RUI-001LD | AO8: =IF(AM8<-2,C8,IF(AL8<-2,C8,"")) | AP8: BI-RUI-006LD | AS8: BI-RUI-005LD | AV8: BI-RUI-006LD
A9: 375 | B9: junio | C9: BI-RUI-001LD | E9: 65.743959 | F9: 61.661502 | G9: 66.184326 | H9: 64.19926 | I9: 63.322566 | J9: 61.107384 | K9: 63.853472 | L9: 61.941887 | M9: 61.623738 | N9: 63.339182 | O9: 68.224253 | P9: 63.42851 | Q9: 66.31593 | R9: 63.590634 | S9: 69.919741 | T9: 62.938087 | U9: 63.432547 | V9: 71.080977 | W9: 64.362993 | X9: 61.047069 | Y9: 68.229767 | Z9: =E9-G9 -> -0.4403675 | AA9: =H9-J9 -> 3.091876 | AB9: =K9-M9 -> 2.2297341 | AC9: =N9-P9 -> -0.089328442 | AD9: =Q9-S9 -> -3.6038106 | AE9: =T9-V9 -> -8.1428901 | AF9: =W9-Y9 -> -3.8667738 | AG9: =E9-F9 -> 4.0824571 | AH9: =F9-G9 -> -4.5228246 | AI9: =K9-L9 -> 1.9115847 | AJ9: =N9-O9 -> -4.8850712 | AK9: =Q9-R9 -> 2.7252963 | AL9: =T9-U9 -> -0.49446006 | AM9: =W9-X9 -> 3.3159243 | AN9: =IF(AF9<-2,C9,IF(AE9<-2,C9,"")) -> BI-RUI-001LD | AO9: =IF(AM9<-2,C9,IF(AL9<-2,C9,"")) | AP9: BI-RUI-008LD | AS9: BI-RUI-006LD | AV9: BI-RUI-007LD
A10: 312 | B10: julio | C10: BI-RUI-001LD | E10: 63.040529 | F10: 60.750734 | G10: 61.745717 | H10: 62.157049 | I10: 61.731882 | J10: 62.849265 | K10: 63.722154 | L10: 62.30274 | M10: 60.092869 | N10: 64.201856 | O10: 63.345898 | P10: 62.448215 | Q10: 64.821695 | R10: 63.262095 | S10: 65.334879 | T10: 61.951915 | U10: 60.85273 | V10: 63.221484 | W10: 60.789284 | X10: 61.425659 | Y10: 59.85832 | Z10: =E10-G10 -> 1.2948111 | AA10: =H10-J10 -> -0.69221583 | AB10: =K10-M10 -> 3.6292846 | AC10: =N10-P10 -> 1.7536412 | AD10: =Q10-S10 -> -0.51318451 | AE10: =T10-V10 -> -1.2695687 | AF10: =W10-Y10 -> 0.93096422 | AG10: =E10-F10 -> 2.2897944 | AH10: =F10-G10 -> -0.99498336 | AI10: =K10-L10 -> 1.4194141 | AJ10: =N10-O10 -> 0.85595862 | AK10: =Q10-R10 -> 1.5596001 | AL10: =T10-U10 -> 1.0991852 | AM10: =W10-X10 -> -0.63637505 | AN10: =IF(AF10<-2,C10,IF(AE10<-2,C10,"")) | AO10: =IF(AM10<-2,C10,IF(AL10<-2,C10,"")) | AP10: BI-RUI-010LD | AS10: BI-RUI-007LD | AV10: BI-RUI-008LD
A11: 63 | B11: agosto | C11: BI-RUI-001LD | E11: 62.745425 | F11: 61.710984 | G11: 60.100114 | H11: 62.882507 | I11: 60.861708 | J11: 61.328807 | K11: 63.262384 | L11: 60.989646 | M11: 61.528371 | N11: 64.063435 | O11: 62.623344 | P11: 60.678892 | Q11: 62.87886 | R11: 61.596343 | S11: 60.790567 | T11: 61.584777 | U11: 66.219949 | V11: 60.719522 | W11: 60.388788 | X11: 63.942898 | Y11: 61.643012 | Z11: =E11-G11 -> 2.645311 | AA11: =H11-J11 -> 1.5536999 | AB11: =K11-M11 -> 1.7340133 | AC11: =N11-P11 -> 3.3845426 | AD11: =Q11-S11 -> 2.0882939 | AE11: =T11-V11 -> 0.86525573 | AF11: =W11-Y11 -> -1.2542245 | AG11: =E11-F11 -> 1.0344408 | AH11: =F11-G11 -> 1.6108703 | AI11: =K11-L11 -> 2.2727375 | AJ11: =N11-O11 -> 1.4400907 | AK11: =Q11-R11 -> 1.2825178 | AL11: =T11-U11 -> -4.6351713 | AM11: =W11-X11 -> -3.5541101 | AN11: =IF(AF11<-2,C11,IF(AE11<-2,C11,"")) | AO11: =IF(AM11<-2,C11,IF(AL11<-2,C11,"")) -> BI-RUI-001LD | AP11: BI-RUI-015LD | AS11: BI-RUI-008LD | AV11: BI-RUI-009LD
A12: 687 | B12: septiembre | C12: BI-RUI-001LD | E12: 63.540125 | F12: 61.130769 | G12: 62.599697 | H12: 62.593602 | I12: 60.915162 | J12: 62.226171 | K12: 63.165486 | L12: 61.198379 | M12: 58.857458 | N12: 64.201542 | O12: 62.841555 | P12: 68.552497 | Q12: 66.437555 | R12: 63.862222 | S12: 67.876653 | T12: 61.013411 | U12: 61.138157 | V12: 67.882189 | W12: 61.48258 | X12: 62.242349 | Y12: 65.501635 | Z12: =E12-G12 -> 0.94042773 | AA12: =H12-J12 -> 0.36743066 | AB12: =K12-M12 -> 4.3080278 | AC12: =N12-P12 -> -4.3509545 | AD12: =Q12-S12 -> -1.4390978 | AE12: =T12-V12 -> -6.8687782 | AF12: =W12-Y12 -> -4.0190549 | AG12: =E12-F12 -> 2.4093559 | AH12: =F12-G12 -> -1.4689281 | AI12: =K12-L12 -> 1.967107 | AJ12: =N12-O12 -> 1.3599868 | AK12: =Q12-R12 -> 2.575333 | AL12: =T12-U12 -> -0.12474605 | AM12: =W12-X12 -> -0.75976927 | AN12: =IF(AF12<-2,C12,IF(AE12<-2,C12,"")) -> BI-RUI-001LD | AO12: =IF(AM12<-2,C12,IF(AL12<-2,C12,"")) | AP12: BI-RUI-016LD | AS12: BI-RUI-009LD | AV12: BI-RUI-010LD
A13: 625 | B13: octubre | C13: BI-RUI-001LD | E13: 62.497209 | F13: 61.921207 | G13: 60.798772 | H13: 64.093417 | I13: 61.342728 | J13: 60.931889 | K13: 65.287561 | L13: 60.559798 | M13: 67.547626 | N13: 65.066084 | O13: 61.011945 | P13: 66.968411 | Q13: 66.847043 | R13: 63.281344 | S13: 69.488448 | T13: 62.39244 | U13: 65.916641 | V13: 70.98869 | W13: 62.548712 | X13: 59.724336 | Y13: 69.740683 | Z13: =E13-G13 -> 1.6984368 | AA13: =H13-J13 -> 3.1615286 | AB13: =K13-M13 -> -2.2600648 | AC13: =N13-P13 -> -1.9023273 | AD13: =Q13-S13 -> -2.6414052 | AE13: =T13-V13 -> -8.5962499 | AF13: =W13-Y13 -> -7.1919716 | AG13: =E13-F13 -> 0.57600214 | AH13: =F13-G13 -> 1.1224347 | AI13: =K13-L13 -> 4.7277633 | AJ13: =N13-O13 -> 4.0541387 | AK13: =Q13-R13 -> 3.5656991 | AL13: =T13-U13 -> -3.5242005 | AM13: =W13-X13 -> 2.8243755 | AN13: =IF(AF13<-2,C13,IF(AE13<-2,C13,"")) -> BI-RUI-001LD | AO13: =IF(AM13<-2,C13,IF(AL13<-2,C13,"")) -> BI-RUI-001LD | AP13: BI-RUI-017LD | AS13: BI-RUI-010LD | AV13: BI-RUI-011LD
A14: 564 | B14: noviembre | C14: BI-RUI-001LD | E14: 64.093063 | F14: 61.045177 | G14: 60.523574 | H14: 63.690975 | I14: 63.082605 | J14: 61.459496 | K14: 62.313455 | L14: 61.303862 | M14: 61.562084 | N14: 63.248242 | O14: 61.249189 | P14: 62.783463 | Q14: 66.29722 | R14: 62.54308 | S14: 68.473099 | T14: 63.156178 | U14: 63.669228 | V14: 70.28848 | W14: 62.845805 | X14: 59.450646 | Y14: 68.76481 | Z14: =E14-G14 -> 3.5694889 | AA14: =H14-J14 -> 2.2314794 | AB14: =K14-M14 -> 0.75137153 | AC14: =N14-P14 -> 0.46477837 | AD14: =Q14-S14 -> -2.1758788 | AE14: =T14-V14 -> -7.1323015 | AF14: =W14-Y14 -> -5.919005 | AG14: =E14-F14 -> 3.0478855 | AH14: =F14-G14 -> 0.52160342 | AI14: =K14-L14 -> 1.0095936 | AJ14: =N14-O14 -> 1.999053 | AK14: =Q14-R14 -> 3.7541405 | AL14: =T14-U14 -> -0.51304995 | AM14: =W14-X14 -> 3.3951584 | AN14: =IF(AF14<-2,C14,IF(AE14<-2,C14,"")) -> BI-RUI-001LD | AO14: =IF(AM14<-2,C14,IF(AL14<-2,C14,"")) | AP14: BI-RUI-020LD | AS14: BI-RUI-011LD | AV14: BI-RUI-013LD
A15: 126 | B15: diciembre | C15: BI-RUI-001LD | E15: 63.684734 | F15: 62.7847 | G15: 65.70116 | H15: 64.827418 | I15: 61.422633 | J15: 66.827531 | K15: 66.494323 | L15: 61.346406 | M15: 68.002551 | N15: 63.464968 | O15: 61.292407 | P15: 67.703661 | Q15: 65.882814 | R15: 62.698584 | S15: 70.079862 | T15: 62.540571 | U15: 61.552031 | V15: 70.396716 | W15: 61.596487 | X15: 60.427748 | Y15: 68.25507 | Z15: =E15-G15 -> -2.0164265 | AA15: =H15-J15 -> -2.0001128 | AB15: =K15-M15 -> -1.5082284 | AC15: =N15-P15 -> -4.2386925 | AD15: =Q15-S15 -> -4.1970482 | AE15: =T15-V15 -> -7.8561445 | AF15: =W15-Y15 -> -6.6585824 | AG15: =E15-F15 -> 0.90003407 | AH15: =F15-G15 -> -2.9164606 | AI15: =K15-L15 -> 5.1479166 | AJ15: =N15-O15 -> 2.1725616 | AK15: =Q15-R15 -> 3.1842299 | AL15: =T15-U15 -> 0.98854074 | AM15: =W15-X15 -> 1.1687397 | AN15: =IF(AF15<-2,C15,IF(AE15<-2,C15,"")) -> BI-RUI-001LD | AO15: =IF(AM15<-2,C15,IF(AL15<-2,C15,"")) | AP15: BI-RUI-021LD | AS15: BI-RUI-013LD | AV15: BI-RUI-015LD
A16: 188 | B16: enero | C16: BI-RUI-004LD | D16: Pza. Unamuno (CV) | E16: 64.761589 | F16: 68.213921 | G16: 57.532225 | H16: 65.512992 | I16: 68.220893 | J16: 58.311112 | K16: 65.533029 | L16: 68.696078 | M16: 58.556881 | N16: 67.491971 | O16: 70.533081 | P16: 59.212971 | Q16: 65.795243 | R16: 70.460899 | S16: 62.016644 | T16: 68.238413 | U16: 71.796387 | V16: 64.678841 | W16: 66.520586 | X16: 65.713852 | Y16: 66.637768 | Z16: =E16-G16 -> 7.2293638 | AA16: =H16-J16 -> 7.2018802 | AB16: =K16-M16 -> 6.9761482 | AC16: =N16-P16 -> 8.2790004 | AD16: =Q16-S16 -> 3.7785997 | AE16: =T16-V16 -> 3.5595712 | AF16: =W16-Y16 -> -0.11718233 | AG16: =E16-F16 -> -3.4523315 | AH16: =F16-G16 -> 10.681695 | AI16: =K16-L16 -> -3.1630488 | AJ16: =N16-O16 -> -3.0411095 | AK16: =Q16-R16 -> -4.6656553 | AL16: =T16-U16 -> -3.5579743 | AM16: =W16-X16 -> 0.80673414 | AN16: =IF(AF16<-2,C16,IF(AE16<-2,C16,"")) | AO16: =IF(AM16<-2,C16,IF(AL16<-2,C16,"")) -> BI-RUI-004LD | AP16: BI-RUI-022LD | AS16: BI-RUI-015LD | AV16: BI-RUI-016LD
A17: 251 | B17: febrero | C17: BI-RUI-004LD | E17: 66.446593 | F17: 66.404902 | G17: 56.937056 | H17: 65.276917 | I17: 66.900307 | J17: 56.288716 | K17: 65.709661 | L17: 67.254606 | M17: 57.710527 | N17: 65.40433 | O17: 69.248019 | P17: 58.969284 | Q17: 69.050071 | R17: 72.360116 | S17: 61.428105 | T17: 71.037982 | U17: 74.908589 | V17: 65.579957 | W17: 68.75923 | X17: 67.073075 | Y17: 66.292757 | Z17: =E17-G17 -> 9.5095366 | AA17: =H17-J17 -> 8.9882016 | AB17: =K17-M17 -> 7.9991332 | AC17: =N17-P17 -> 6.4350463 | AD17: =Q17-S17 -> 7.6219655 | AE17: =T17-V17 -> 5.4580249 | AF17: =W17-Y17 -> 2.4664732 | AG17: =E17-F17 -> 0.04169128 | AH17: =F17-G17 -> 9.4678454 | AI17: =K17-L17 -> -1.5449453 | AJ17: =N17-O17 -> -3.8436887 | AK17: =Q17-R17 -> -3.310045 | AL17: =T17-U17 -> -3.8706069 | AM17: =W17-X17 -> 1.6861552 | AN17: =IF(AF17<-2,C17,IF(AE17<-2,C17,"")) | AO17: =IF(AM17<-2,C17,IF(AL17<-2,C17,"")) -> BI-RUI-004LD | AP17: BI-RUI-023LD | AS17: BI-RUI-016LD | AV17: BI-RUI-017LD
A18: 439 | B18: marzo | C18: BI-RUI-004LD | E18: 67.676599 | F18: 65.61431 | G18: 57.027094 | H18: 67.718689 | I18: 67.544187 | J18: 56.64305 | K18: 68.458269 | L18: 68.609381 | M18: 56.962344 | N18: 67.522653 | O18: 69.187349 | P18: 59.127803 | Q18: 69.144884 | R18: 71.712842 | S18: 61.935353 | T18: 69.687961 | U18: 72.797538 | V18: 65.411172 | W18: 68.768498 | X18: 66.485183 | Y18: 63.950869 | Z18: =E18-G18 -> 10.649505 | AA18: =H18-J18 -> 11.075639 | AB18: =K18-M18 -> 11.495925 | AC18: =N18-P18 -> 8.3948504 | AD18: =Q18-S18 -> 7.2095312 | AE18: =T18-V18 -> 4.2767897 | AF18: =W18-Y18 -> 4.8176294 | AG18: =E18-F18 -> 2.0622893 | AH18: =F18-G18 -> 8.587216 | AI18: =K18-L18 -> -0.15111184 | AJ18: =N18-O18 -> -1.6646954 | AK18: =Q18-R18 -> -2.5679581 | AL18: =T18-U18 -> -3.1095765 | AM18: =W18-X18 -> 2.2833148 | AN18: =IF(AF18<-2,C18,IF(AE18<-2,C18,"")) | AO18: =IF(AM18<-2,C18,IF(AL18<-2,C18,"")) -> BI-RUI-004LD | AP18: BI-RUI-025LD | AS18: BI-RUI-017LD | AV18: BI-RUI-019LD
A19: 1 | B19: abril | C19: BI-RUI-004LD | E19: 69.018845 | F19: 68.091628 | G19: 59.217068 | H19: 69.047851 | I19: 68.613175 | J19: 57.353666 | K19: 66.391025 | L19: 70.05673 | M19: 59.228974 | N19: 66.84793 | O19: 71.276674 | P19: 60.763876 | Q19: 68.243687 | R19: 72.303599 | S19: 63.403631 | T19: 71.208768 | U19: 73.222843 | V19: 64.78724 | W19: 67.848316 | X19: 68.988711 | Y19: 64.606171 | Z19: =E19-G19 -> 9.8017768 | AA19: =H19-J19 -> 11.694184 | AB19: =K19-M19 -> 7.1620511 | AC19: =N19-P19 -> 6.0840541 | AD19: =Q19-S19 -> 4.840056 | AE19: =T19-V19 -> 6.4215274 | AF19: =W19-Y19 -> 3.2421456 | AG19: =E19-F19 -> 0.92721669 | AH19: =F19-G19 -> 8.8745602 | AI19: =K19-L19 -> -3.6657048 | AJ19: =N19-O19 -> -4.428744 | AK19: =Q19-R19 -> -4.0599116 | AL19: =T19-U19 -> -2.0140753 | AM19: =W19-X19 -> -1.1403944 | AN19: =IF(AF19<-2,C19,IF(AE19<-2,C19,"")) | AO19: =IF(AM19<-2,C19,IF(AL19<-2,C19,"")) -> BI-RUI-004LD | AP19: BI-RUI-BR15LD | AS19: BI-RUI-020LD | AV19: BI-RUI-020LD
A20: 502 | B20: mayo | C20: BI-RUI-004LD | E20: 68.06413 | F20: 69.387554 | G20: 60.106318 | H20: 67.443766 | I20: 67.942824 | J20: 58.637974 | K20: 66.944019 | L20: 69.501999 | M20: 58.670231 | N20: 66.769346 | O20: 68.280795 | P20: 59.300737 | Q20: 69.304972 | R20: 71.87118 | S20: 62.400186 | T20: 68.597063 | U20: 73.183896 | V20: 66.410921 | W20: 67.791881 | X20: 68.68344 | Y20: 65.458408 | Z20: =E20-G20 -> 7.9578119 | AA20: =H20-J20 -> 8.8057925 | AB20: =K20-M20 -> 8.2737882 | AC20: =N20-P20 -> 7.4686087 | AD20: =Q20-S20 -> 6.9047861 | AE20: =T20-V20 -> 2.1861411 | AF20: =W20-Y20 -> 2.3334734 | AG20: =E20-F20 -> -1.3234237 | AH20: =F20-G20 -> 9.2812357 | AI20: =K20-L20 -> -2.55798 | AJ20: =N20-O20 -> -1.5114491 | AK20: =Q20-R20 -> -2.5662077 | AL20: =T20-U20 -> -4.5868333 | AM20: =W20-X20 -> -0.89155833 | AN20: =IF(AF20<-2,C20,IF(AE20<-2,C20,"")) | AO20: =IF(AM20<-2,C20,IF(AL20<-2,C20,"")) -> BI-RUI-004LD | AP20: BI-RUI-BR1LD | AS20: BI-RUI-021LD | AV20: BI-RUI-021LD
A21: 376 | B21: junio | C21: BI-RUI-004LD | E21: 67.936733 | F21: 68.264736 | G21: 59.44396 | H21: 67.902285 | I21: 70.273719 | J21: 60.326036 | K21: 68.25729 | L21: 71.231871 | M21: 59.927718 | N21: 67.556618 | O21: 71.864829 | P21: 61.044915 | Q21: 68.621382 | R21: 73.75081 | S21: 63.852185 | T21: 70.279963 | U21: 72.703325 | V21: 66.309543 | W21: 68.561027 | X21: 67.586943 | Y21: 66.31065 | Z21: =E21-G21 -> 8.4927736 | AA21: =H21-J21 -> 7.5762486 | AB21: =K21-M21 -> 8.3295719 | AC21: =N21-P21 -> 6.5117029 | AD21: =Q21-S21 -> 4.7691971 | AE21: =T21-V21 -> 3.9704197 | AF21: =W21-Y21 -> 2.2503773 | AG21: =E21-F21 -> -0.32800259 | AH21: =F21-G21 -> 8.8207762 | AI21: =K21-L21 -> -2.9745803 | AJ21: =N21-O21 -> -4.3082112 | AK21: =Q21-R21 -> -5.1294276 | AL21: =T21-U21 -> -2.4233623 | AM21: =W21-X21 -> 0.97408432 | AN21: =IF(AF21<-2,C21,IF(AE21<-2,C21,"")) | AO21: =IF(AM21<-2,C21,IF(AL21<-2,C21,"")) -> BI-RUI-004LD | AP21: BI-RUI-BR2LD | AS21: BI-RUI-022LD | AV21: BI-RUI-022LD
A22: 313 | B22: julio | C22: BI-RUI-004LD | E22: 65.590897 | F22: 68.448254 | G22: 60.498929 | H22: 66.126974 | I22: 68.953812 | J22: 59.89151 | K22: 68.310729 | L22: 71.128698 | M22: 60.469588 | N22: 66.191658 | O22: 70.296364 | P22: 61.483952 | Q22: 66.777348 | R22: 70.719103 | S22: 62.479627 | T22: 67.648677 | U22: 73.200122 | V22: 66.867847 | W22: 66.744897 | X22: 70.152624 | Y22: 66.07259 | Z22: =E22-G22 -> 5.091968 | AA22: =H22-J22 -> 6.2354641 | AB22: =K22-M22 -> 7.841141 | AC22: =N22-P22 -> 4.7077056 | AD22: =Q22-S22 -> 4.2977215 | AE22: =T22-V22 -> 0.78082995 | AF22: =W22-Y22 -> 0.67230736 | AG22: =E22-F22 -> -2.8573575 | AH22: =F22-G22 -> 7.9493255 | AI22: =K22-L22 -> -2.817969 | AJ22: =N22-O22 -> -4.1047066 | AK22: =Q22-R22 -> -3.9417545 | AL22: =T22-U22 -> -5.5514451 | AM22: =W22-X22 -> -3.407727 | AN22: =IF(AF22<-2,C22,IF(AE22<-2,C22,"")) | AO22: =IF(AM22<-2,C22,IF(AL22<-2,C22,"")) -> BI-RUI-004LD | AP22: BI-RUI-BR5LD | AS22: BI-RUI-023LD | AV22: BI-RUI-023LD
A23: 64 | B23: agosto | C23: BI-RUI-004LD | E23: 67.211619 | F23: 74.627459 | G23: 65.339525 | H23: 67.922522 | I23: 71.900283 | J23: 64.975718 | K23: 67.891207 | L23: 70.510969 | M23: 64.905093 | N23: 68.539866 | O23: 78.657881 | P23: 66.896692 | Q23: 70.78965 | R23: 75.611844 | S23: 68.834583 | T23: 71.70931 | U23: 74.92972 | V23: 69.187354 | W23: 71.184442 | X23: 71.171061 | Y23: 69.852775 | Z23: =E23-G23 -> 1.8720942 | AA23: =H23-J23 -> 2.9468041 | AB23: =K23-M23 -> 2.9861142 | AC23: =N23-P23 -> 1.6431744 | AD23: =Q23-S23 -> 1.9550668 | AE23: =T23-V23 -> 2.5219554 | AF23: =W23-Y23 -> 1.3316667 | AG23: =E23-F23 -> -7.41584 | AH23: =F23-G23 -> 9.2879343 | AI23: =K23-L23 -> -2.6197613 | AJ23: =N23-O23 -> -10.118015 | AK23: =Q23-R23 -> -4.8221942 | AL23: =T23-U23 -> -3.2204109 | AM23: =W23-X23 -> 0.013380706 | AN23: =IF(AF23<-2,C23,IF(AE23<-2,C23,"")) | AO23: =IF(AM23<-2,C23,IF(AL23<-2,C23,"")) -> BI-RUI-004LD | AP23: BI-RUI-BR8LD | AS23: BI-RUI-025LD | AV23: BI-RUI-025LD
A24: 688 | B24: septiembre | C24: BI-RUI-004LD | E24: 64.929476 | F24: 68.115162 | G24: 61.990691 | H24: 65.23248 | I24: 68.678352 | J24: 63.077197 | K24: 66.10992 | L24: 69.537016 | M24: 63.734144 | N24: 65.404049 | O24: 68.675446 | P24: 60.636404 | Q24: 65.97585 | R24: 71.429843 | S24: 62.341191 | T24: 66.345659 | U24: 72.214658 | V24: 66.837168 | W24: 65.015259 | X24: 67.92196 | Y24: 65.242807 | Z24: =E24-G24 -> 2.9387854 | AA24: =H24-J24 -> 2.1552838 | AB24: =K24-M24 -> 2.375776 | AC24: =N24-P24 -> 4.7676447 | AD24: =Q24-S24 -> 3.6346595 | AE24: =T24-V24 -> -0.49150979 | AF24: =W24-Y24 -> -0.22754787 | AG24: =E24-F24 -> -3.1856858 | AH24: =F24-G24 -> 6.1244712 | AI24: =K24-L24 -> -3.4270959 | AJ24: =N24-O24 -> -3.2713968 | AK24: =Q24-R24 -> -5.4539925 | AL24: =T24-U24 -> -5.8689999 | AM24: =W24-X24 -> -2.9067016 | AN24: =IF(AF24<-2,C24,IF(AE24<-2,C24,"")) | AO24: =IF(AM24<-2,C24,IF(AL24<-2,C24,"")) -> BI-RUI-004LD | AP24: BI-RUI-C001LD | AS24: BI-RUI-BR11LD | AV24: BI-RUI-BR11LD
A25: 626 | B25: octubre | C25: BI-RUI-004LD | E25: 66.259685 | F25: 68.623017 | G25: 59.296636 | H25: 65.787641 | I25: 72.224923 | J25: 61.052091 | K25: 66.765208 | L25: 70.440434 | M25: 62.221725 | N25: 67.621152 | O25: 71.759474 | P25: 62.271312 | Q25: 67.890343 | R25: 73.459642 | S25: 63.343895 | T25: 69.991571 | U25: 73.908388 | V25: 66.105256 | W25: 68.291192 | X25: 68.302838 | Y25: 66.299142 | Z25: =E25-G25 -> 6.9630483 | AA25: =H25-J25 -> 4.7355495 | AB25: =K25-M25 -> 4.5434821 | AC25: =N25-P25 -> 5.34984 | AD25: =Q25-S25 -> 4.5464481 | AE25: =T25-V25 -> 3.8863149 | AF25: =W25-Y25 -> 1.9920502 | AG25: =E25-F25 -> -2.3633323 | AH25: =F25-G25 -> 9.3263806 | AI25: =K25-L25 -> -3.675226 | AJ25: =N25-O25 -> -4.1383224 | AK25: =Q25-R25 -> -5.5692992 | AL25: =T25-U25 -> -3.9168172 | AM25: =W25-X25 -> -0.011645984 | AN25: =IF(AF25<-2,C25,IF(AE25<-2,C25,"")) | AO25: =IF(AM25<-2,C25,IF(AL25<-2,C25,"")) -> BI-RUI-004LD | AP25: BI-RUI-C002LD | AS25: BI-RUI-BR15LD | AV25: BI-RUI-BR15LD
A26: 565 | B26: noviembre | C26: BI-RUI-004LD | E26: 68.471143 | F26: 65.198854 | G26: 69.389389 | H26: 67.710145 | I26: 65.539172 | J26: 61.3345 | K26: 68.562038 | L26: 69.597474 | M26: 57.759757 | N26: 68.559693 | O26: 68.313703 | P26: 58.497897 | Q26: 68.422891 | R26: 70.917175 | S26: 62.06357 | T26: 70.02842 | U26: 73.27566 | V26: 65.599062 | W26: 67.872365 | X26: 67.464381 | Y26: 67.324874 | Z26: =E26-G26 -> -0.91824538 | AA26: =H26-J26 -> 6.375645 | AB26: =K26-M26 -> 10.802281 | AC26: =N26-P26 -> 10.061796 | AD26: =Q26-S26 -> 6.3593205 | AE26: =T26-V26 -> 4.429358 | AF26: =W26-Y26 -> 0.54749024 | AG26: =E26-F26 -> 3.2722889 | AH26: =F26-G26 -> -4.1905343 | AI26: =K26-L26 -> -1.035436 | AJ26: =N26-O26 -> 0.24599022 | AK26: =Q26-R26 -> -2.4942847 | AL26: =T26-U26 -> -3.2472408 | AM26: =W26-X26 -> 0.40798303 | AN26: =IF(AF26<-2,C26,IF(AE26<-2,C26,"")) | AO26: =IF(AM26<-2,C26,IF(AL26<-2,C26,"")) -> BI-RUI-004LD | AP26: BI-RUI-C003LD | AS26: BI-RUI-BR1LD | AV26: BI-RUI-BR1LD
A27: 127 | B27: diciembre | C27: BI-RUI-004LD | E27: 65.349447 | F27: 70.099951 | G27: 58.013608 | H27: 68.220762 | I27: 70.627137 | J27: 58.987714 | K27: 70.870074 | L27: 73.808482 | M27: 63.054437 | N27: 68.332301 | O27: 70.289649 | P27: 63.357557 | Q27: 68.116769 | R27: 74.506532 | S27: 64.174142 | T27: 69.614294 | U27: 74.607286 | V27: 66.058134 | W27: 67.776911 | X27: 68.830741 | Y27: 64.462485 | Z27: =E27-G27 -> 7.3358399 | AA27: =H27-J27 -> 9.233048 | AB27: =K27-M27 -> 7.8156377 | AC27: =N27-P27 -> 4.9747439 | AD27: =Q27-S27 -> 3.9426274 | AE27: =T27-V27 -> 3.55616 | AF27: =W27-Y27 -> 3.3144256 | AG27: =E27-F27 -> -4.7505036 | AH27: =F27-G27 -> 12.086343 | AI27: =K27-L27 -> -2.9384083 | AJ27: =N27-O27 -> -1.9573478 | AK27: =Q27-R27 -> -6.3897627 | AL27: =T27-U27 -> -4.9929912 | AM27: =W27-X27 -> -1.05383 | AN27: =IF(AF27<-2,C27,IF(AE27<-2,C27,"")) | AO27: =IF(AM27<-2,C27,IF(AL27<-2,C27,"")) -> BI-RUI-004LD | AP27: BI-RUI-C004LD | AS27: BI-RUI-BR2LD | AV27: BI-RUI-BR2LD
A28: 189 | B28: enero | C28: BI-RUI-005LD | D28: María Muñoz (CV) | E28: 68.450649 | F28: 67.225161 | G28: 57.986071 | H28: 68.713532 | I28: 67.315363 | J28: 59.789433 | K28: 68.369754 | L28: 68.412623 | M28: 58.167786 | N28: 67.743005 | O28: 69.064507 | P28: 60.693216 | Q28: 68.563173 | R28: 71.164045 | S28: 64.162464 | T28: 69.692884 | U28: 73.37205 | V28: 66.210847 | W28: 68.70828 | X28: 66.146745 | Y28: 67.277174 | Z28: =E28-G28 -> 10.464578 | AA28: =H28-J28 -> 8.9240987 | AB28: =K28-M28 -> 10.201968 | AC28: =N28-P28 -> 7.0497894 | AD28: =Q28-S28 -> 4.4007094 | AE28: =T28-V28 -> 3.4820363 | AF28: =W28-Y28 -> 1.4311061 | AG28: =E28-F28 -> 1.2254886 | AH28: =F28-G28 -> 9.2390894 | AI28: =K28-L28 -> -0.042868603 | AJ28: =N28-O28 -> -1.3215019 | AK28: =Q28-R28 -> -2.6008718 | AL28: =T28-U28 -> -3.6791661 | AM28: =W28-X28 -> 2.5615349 | AN28: =IF(AF28<-2,C28,IF(AE28<-2,C28,"")) | AO28: =IF(AM28<-2,C28,IF(AL28<-2,C28,"")) -> BI-RUI-005LD | AP28: BI-RUI-C005LD | AS28: BI-RUI-BR5LD | AV28: BI-RUI-BR5LD
A29: 252 | B29: febrero | C29: BI-RUI-005LD | E29: 69.625853 | F29: 67.97252 | G29: 57.727613 | H29: 70.706307 | I29: 68.597047 | J29: 56.312663 | K29: 71.153379 | L29: 68.266934 | M29: 58.262235 | N29: 69.476644 | O29: 71.174269 | P29: 61.118528 | Q29: 69.292508 | R29: 71.700998 | S29: 64.536093 | T29: 70.172912 | U29: 74.483384 | V29: 65.597969 | W29: 68.701458 | X29: 67.532473 | Y29: 66.107296 | Z29: =E29-G29 -> 11.89824 | AA29: =H29-J29 -> 14.393644 | AB29: =K29-M29 -> 12.891144 | AC29: =N29-P29 -> 8.3581159 | AD29: =Q29-S29 -> 4.7564148 | AE29: =T29-V29 -> 4.574943 | AF29: =W29-Y29 -> 2.5941621 | AG29: =E29-F29 -> 1.6533323 | AH29: =F29-G29 -> 10.244907 | AI29: =K29-L29 -> 2.8864451 | AJ29: =N29-O29 -> -1.6976248 | AK29: =Q29-R29 -> -2.4084895 | AL29: =T29-U29 -> -4.3104714 | AM29: =W29-X29 -> 1.1689853 | AN29: =IF(AF29<-2,C29,IF(AE29<-2,C29,"")) | AO29: =IF(AM29<-2,C29,IF(AL29<-2,C29,"")) -> BI-RUI-005LD | AP29: BI-RUI-C006LD | AS29: BI-RUI-BR6LD | AV29: BI-RUI-BR6LD
A30: 440 | B30: marzo | C30: BI-RUI-005LD | E30: 71.22423 | F30: 69.988737 | G30: 59.803384 | H30: 70.791096 | I30: 70.097907 | J30: 59.26516 | K30: 71.115042 | L30: 71.127213 | M30: 59.318543 | N30: 71.157979 | O30: 73.197196 | P30: 62.529582 | Q30: 71.592548 | R30: 74.120272 | S30: 67.275063 | T30: 70.181307 | U30: 74.94726 | V30: 65.974208 | W30: 70.119827 | X30: 67.871048 | Y30: 64.897051 | Z30: =E30-G30 -> 11.420846 | AA30: =H30-J30 -> 11.525935 | AB30: =K30-M30 -> 11.796499 | AC30: =N30-P30 -> 8.6283974 | AD30: =Q30-S30 -> 4.3174847 | AE30: =T30-V30 -> 4.2070992 | AF30: =W30-Y30 -> 5.2227762 | AG30: =E30-F30 -> 1.2354926 | AH30: =F30-G30 -> 10.185353 | AI30: =K30-L30 -> -0.012170725 | AJ30: =N30-O30 -> -2.0392167 | AK30: =Q30-R30 -> -2.5277245 | AL30: =T30-U30 -> -4.7659529 | AM30: =W30-X30 -> 2.2487789 | AN30: =IF(AF30<-2,C30,IF(AE30<-2,C30,"")) | AO30: =IF(AM30<-2,C30,IF(AL30<-2,C30,"")) -> BI-RUI-005LD | AP30: BI-RUI-C008LD | AS30: BI-RUI-BR8LD | AV30: BI-RUI-BR7LD
A31: 2 | B31: abril | C31: BI-RUI-005LD | E31: 69.856573 | F31: 71.054966 | G31: 59.504072 | H31: 71.146393 | I31: 70.597427 | J31: 59.430984 | K31: 70.28582 | L31: 71.631912 | M31: 61.162871 | N31: 71.446854 | O31: 72.512552 | P31: 62.717062 | Q31: 70.117082 | R31: 73.157868 | S31: 65.770906 | T31: 69.993332 | U31: 73.656602 | V31: 66.333839 | W31: 70.820548 | X31: 71.790355 | Y31: 65.017348 | Z31: =E31-G31 -> 10.352502 | AA31: =H31-J31 -> 11.715409 | AB31: =K31-M31 -> 9.1229482 | AC31: =N31-P31 -> 8.7297919 | AD31: =Q31-S31 -> 4.3461761 | AE31: =T31-V31 -> 3.6594931 | AF31: =W31-Y31 -> 5.8031998 | AG31: =E31-F31 -> -1.1983923 | AH31: =F31-G31 -> 11.550894 | AI31: =K31-L31 -> -1.3460927 | AJ31: =N31-O31 -> -1.065698 | AK31: =Q31-R31 -> -3.0407864 | AL31: =T31-U31 -> -3.6632694 | AM31: =W31-X31 -> -0.96980722 | AN31: =IF(AF31<-2,C31,IF(AE31<-2,C31,"")) | AO31: =IF(AM31<-2,C31,IF(AL31<-2,C31,"")) -> BI-RUI-005LD | AP31: BI-RUI-C009LD | AS31: BI-RUI-C001LD | AV31: BI-RUI-BR8LD
A32: 503 | B32: mayo | C32: BI-RUI-005LD | E32: 69.282081 | F32: 70.029325 | G32: 60.341678 | H32: 69.641647 | I32: 70.062532 | J32: 58.37882 | K32: 69.03436 | L32: 71.616653 | M32: 60.04313 | N32: 68.694121 | O32: 70.948849 | P32: 61.083649 | Q32: 70.303159 | R32: 73.504636 | S32: 65.551062 | T32: 71.169157 | U32: 74.74555 | V32: 67.014303 | W32: 69.660936 | X32: 69.557284 | Y32: 65.171316 | Z32: =E32-G32 -> 8.9404029 | AA32: =H32-J32 -> 11.262828 | AB32: =K32-M32 -> 8.9912301 | AC32: =N32-P32 -> 7.6104722 | AD32: =Q32-S32 -> 4.7520966 | AE32: =T32-V32 -> 4.1548532 | AF32: =W32-Y32 -> 4.4896208 | AG32: =E32-F32 -> -0.74724328 | AH32: =F32-G32 -> 9.6876462 | AI32: =K32-L32 -> -2.5822926 | AJ32: =N32-O32 -> -2.2547279 | AK32: =Q32-R32 -> -3.2014777 | AL32: =T32-U32 -> -3.5763933 | AM32: =W32-X32 -> 0.10365269 | AN32: =IF(AF32<-2,C32,IF(AE32<-2,C32,"")) | AO32: =IF(AM32<-2,C32,IF(AL32<-2,C32,"")) -> BI-RUI-005LD | AP32: BI-RUI-C010LD | AS32: BI-RUI-C002LD | AV32: BI-RUI-C001LD
A33: 377 | B33: junio | C33: BI-RUI-005LD | E33: 71.319382 | F33: 70.532668 | G33: 58.952832 | H33: 72.43773 | I33: 70.667619 | J33: 58.808769 | K33: 71.291206 | L33: 72.239241 | M33: 59.720768 | N33: 70.62788 | O33: 72.307161 | P33: 61.028773 | Q33: 70.907194 | R33: 74.761255 | S33: 67.761344 | T33: 70.857286 | U33: 74.56408 | V33: 67.950966 | W33: 70.42971 | X33: 69.973648 | Y33: 65.512807 | Z33: =E33-G33 -> 12.36655 | AA33: =H33-J33 -> 13.628961 | AB33: =K33-M33 -> 11.570438 | AC33: =N33-P33 -> 9.599107 | AD33: =Q33-S33 -> 3.1458503 | AE33: =T33-V33 -> 2.9063192 | AF33: =W33-Y33 -> 4.9169026 | AG33: =E33-F33 -> 0.78671381 | AH33: =F33-G33 -> 11.579836 | AI33: =K33-L33 -> -0.94803546 | AJ33: =N33-O33 -> -1.6792802 | AK33: =Q33-R33 -> -3.8540614 | AL33: =T33-U33 -> -3.7067945 | AM33: =W33-X33 -> 0.4560615 | AN33: =IF(AF33<-2,C33,IF(AE33<-2,C33,"")) | AO33: =IF(AM33<-2,C33,IF(AL33<-2,C33,"")) -> BI-RUI-005LD | AP33: BI-RUI-C011LD | AS33: BI-RUI-C003LD | AV33: BI-RUI-C002LD
A34: 314 | B34: julio | C34: BI-RUI-005LD | E34: 68.120276 | F34: 72.40594 | G34: 60.586245 | H34: 69.011935 | I34: 71.180721 | J34: 60.47464 | K34: 69.178261 | L34: 71.54818 | M34: 61.349136 | N34: 69.651912 | O34: 71.844399 | P34: 61.304628 | Q34: 68.91735 | R34: 73.14139 | S34: 64.368645 | T34: 69.6968 | U34: 73.376975 | V34: 65.515836 | W34: 68.663198 | X34: 69.147592 | Y34: 64.152896 | Z34: =E34-G34 -> 7.5340306 | AA34: =H34-J34 -> 8.5372957 | AB34: =K34-M34 -> 7.8291256 | AC34: =N34-P34 -> 8.3472839 | AD34: =Q34-S34 -> 4.548705 | AE34: =T34-V34 -> 4.1809641 | AF34: =W34-Y34 -> 4.5103026 | AG34: =E34-F34 -> -4.2856642 | AH34: =F34-G34 -> 11.819695 | AI34: =K34-L34 -> -2.3699192 | AJ34: =N34-O34 -> -2.192487 | AK34: =Q34-R34 -> -4.2240401 | AL34: =T34-U34 -> -3.6801748 | AM34: =W34-X34 -> -0.48439408 | AN34: =IF(AF34<-2,C34,IF(AE34<-2,C34,"")) | AO34: =IF(AM34<-2,C34,IF(AL34<-2,C34,"")) -> BI-RUI-005LD | AP34: BI-RUI-C015LD | AS34: BI-RUI-C004LD | AV34: BI-RUI-C003LD
A35: 65 | B35: agosto | C35: BI-RUI-005LD | E35: 69.667231 | F35: 73.254063 | G35: 65.123675 | H35: 70.207091 | I35: 72.800524 | J35: 63.846544 | K35: 70.017804 | L35: 72.966104 | M35: 63.549784 | N35: 71.234442 | O35: 74.685227 | P35: 67.938018 | Q35: 73.117292 | R35: 74.493729 | S35: 68.969756 | T35: 72.547254 | U35: 75.217537 | V35: 68.618192 | W35: 70.828322 | X35: 72.689014 | Y35: 67.334565 | Z35: =E35-G35 -> 4.5435559 | AA35: =H35-J35 -> 6.3605475 | AB35: =K35-M35 -> 6.4680206 | AC35: =N35-P35 -> 3.2964235 | AD35: =Q35-S35 -> 4.147536 | AE35: =T35-V35 -> 3.9290616 | AF35: =W35-Y35 -> 3.4937575 | AG35: =E35-F35 -> -3.5868325 | AH35: =F35-G35 -> 8.1303884 | AI35: =K35-L35 -> -2.9483002 | AJ35: =N35-O35 -> -3.4507852 | AK35: =Q35-R35 -> -1.3764372 | AL35: =T35-U35 -> -2.6702828 | AM35: =W35-X35 -> -1.8606921 | AN35: =IF(AF35<-2,C35,IF(AE35<-2,C35,"")) | AO35: =IF(AM35<-2,C35,IF(AL35<-2,C35,"")) -> BI-RUI-005LD | AP35: BI-RUI-C017LD | AS35: BI-RUI-C005LD | AV35: BI-RUI-C004LD
A36: 689 | B36: septiembre | C36: BI-RUI-005LD | E36: 68.200141 | F36: 71.95328 | G36: 62.919719 | H36: 69.016291 | I36: 71.47686 | J36: 64.03691 | K36: 69.691374 | L36: 71.726417 | M36: 63.319788 | N36: 68.288053 | O36: 72.750838 | P36: 62.984318 | Q36: 68.710184 | R36: 72.70258 | S36: 65.405159 | T36: 69.16152 | U36: 73.765182 | V36: 67.484121 | W36: 68.444981 | X36: 70.952833 | Y36: 65.147553 | Z36: =E36-G36 -> 5.2804218 | AA36: =H36-J36 -> 4.9793815 | AB36: =K36-M36 -> 6.3715864 | AC36: =N36-P36 -> 5.3037357 | AD36: =Q36-S36 -> 3.3050256 | AE36: =T36-V36 -> 1.6773995 | AF36: =W36-Y36 -> 3.2974277 | AG36: =E36-F36 -> -3.7531396 | AH36: =F36-G36 -> 9.0335615 | AI36: =K36-L36 -> -2.035043 | AJ36: =N36-O36 -> -4.462785 | AK36: =Q36-R36 -> -3.9923955 | AL36: =T36-U36 -> -4.6036612 | AM36: =W36-X36 -> -2.507852 | AN36: =IF(AF36<-2,C36,IF(AE36<-2,C36,"")) | AO36: =IF(AM36<-2,C36,IF(AL36<-2,C36,"")) -> BI-RUI-005LD | AP36: BI-RUI-C018LD | AS36: BI-RUI-C006LD | AV36: BI-RUI-C005LD
A37: 627 | B37: octubre | C37: BI-RUI-005LD | E37: 68.667815 | F37: 70.645613 | G37: 61.662311 | H37: 67.886713 | I37: 72.033463 | J37: 63.352327 | K37: 67.738647 | L37: 71.611851 | M37: 63.078905 | N37: 67.814882 | O37: 71.934966 | P37: 64.240663 | Q37: 68.542697 | R37: 74.585616 | S37: 69.121222 | T37: 70.413842 | U37: 74.59721 | V37: 68.002581 | W37: 69.960256 | X37: 70.523392 | Y37: 65.54339 | Z37: =E37-G37 -> 7.0055044 | AA37: =H37-J37 -> 4.5343861 | AB37: =K37-M37 -> 4.6597416 | AC37: =N37-P37 -> 3.5742192 | AD37: =Q37-S37 -> -0.57852433 | AE37: =T37-V37 -> 2.4112611 | AF37: =W37-Y37 -> 4.4168658 | AG37: =E37-F37 -> -1.9777978 | AH37: =F37-G37 -> 8.9833022 | AI37: =K37-L37 -> -3.8732044 | AJ37: =N37-O37 -> -4.1200841 | AK37: =Q37-R37 -> -6.0429181 | AL37: =T37-U37 -> -4.1833673 | AM37: =W37-X37 -> -0.56313556 | AN37: =IF(AF37<-2,C37,IF(AE37<-2,C37,"")) | AO37: =IF(AM37<-2,C37,IF(AL37<-2,C37,"")) -> BI-RUI-005LD | AP37: BI-RUI-C019LD | AS37: BI-RUI-C008LD | AV37: BI-RUI-C006LD
A38: 566 | B38: noviembre | C38: BI-RUI-005LD | E38: 68.177866 | F38: 67.415605 | G38: 57.004803 | H38: 69.641588 | I38: 67.921264 | J38: 61.105463 | K38: 68.894994 | L38: 69.772436 | M38: 59.611482 | N38: 67.897079 | O38: 69.91205 | P38: 61.004528 | Q38: 69.264447 | R38: 72.285006 | S38: 66.05591 | T38: 70.447631 | U38: 73.801092 | V38: 66.371098 | W38: 69.809893 | X38: 69.42853 | Y38: 65.598216 | Z38: =E38-G38 -> 11.173063 | AA38: =H38-J38 -> 8.5361247 | AB38: =K38-M38 -> 9.2835118 | AC38: =N38-P38 -> 6.8925514 | AD38: =Q38-S38 -> 3.2085367 | AE38: =T38-V38 -> 4.0765327 | AF38: =W38-Y38 -> 4.211677 | AG38: =E38-F38 -> 0.76226064 | AH38: =F38-G38 -> 10.410802 | AI38: =K38-L38 -> -0.8774423 | AJ38: =N38-O38 -> -2.0149708 | AK38: =Q38-R38 -> -3.0205591 | AL38: =T38-U38 -> -3.3534617 | AM38: =W38-X38 -> 0.38136265 | AN38: =IF(AF38<-2,C38,IF(AE38<-2,C38,"")) | AO38: =IF(AM38<-2,C38,IF(AL38<-2,C38,"")) -> BI-RUI-005LD | AP38: BI-RUI-C020LD | AS38: BI-RUI-C009LD | AV38: BI-RUI-C008LD
A39: 128 | B39: diciembre | C39: BI-RUI-005LD | E39: 69.278028 | F39: 70.245261 | G39: 59.606869 | H39: 71.850853 | I39: 69.922121 | J39: 59.550862 | K39: 71.371591 | L39: 74.057862 | M39: 64.214244 | N39: 69.642043 | O39: 70.598701 | P39: 66.429196 | Q39: 69.300193 | R39: 73.763025 | S39: 65.218505 | T39: 70.433627 | U39: 73.155502 | V39: 65.41615 | W39: 69.282664 | X39: 67.95395 | Y39: 63.669842 | Z39: =E39-G39 -> 9.6711588 | AA39: =H39-J39 -> 12.299992 | AB39: =K39-M39 -> 7.1573464 | AC39: =N39-P39 -> 3.212847 | AD39: =Q39-S39 -> 4.0816888 | AE39: =T39-V39 -> 5.0174764 | AF39: =W39-Y39 -> 5.6128225 | AG39: =E39-F39 -> -0.96723256 | AH39: =F39-G39 -> 10.638391 | AI39: =K39-L39 -> -2.6862713 | AJ39: =N39-O39 -> -0.95665754 | AK39: =Q39-R39 -> -4.4628318 | AL39: =T39-U39 -> -2.7218751 | AM39: =W39-X39 -> 1.3287139 | AN39: =IF(AF39<-2,C39,IF(AE39<-2,C39,"")) | AO39: =IF(AM39<-2,C39,IF(AL39<-2,C39,"")) -> BI-RUI-005LD | AP39: BI-RUI-C021LD | AS39: BI-RUI-C010LD | AV39: BI-RUI-C009LD
A40: 190 | B40: enero | C40: BI-RUI-006LD | E40: 61.840568 | F40: 62.126638 | G40: 60.219104 | H40: 61.517923 | I40: 62.248047 | J40: 59.880225 | K40: 61.636335 | L40: 61.89615 | M40: 59.284186 | N40: 62.936762 | O40: 68.107961 | P40: 64.473125 | Q40: 63.481404 | R40: 72.672976 | S40: 70.765445 | T40: 65.776969 | U40: 76.424668 | V40: 75.263204 | W40: 68.080727 | X40: 63.679566 | Y40: 75.149821 | Z40: =E40-G40 -> 1.6214631 | AA40: =H40-J40 -> 1.6376981 | AB40: =K40-M40 -> 2.3521494 | AC40: =N40-P40 -> -1.5363624 | AD40: =Q40-S40 -> -7.284041 | AE40: =T40-V40 -> -9.4862353 | AF40: =W40-Y40 -> -7.0690941 | AG40: =E40-F40 -> -0.28607024 | AH40: =F40-G40 -> 1.9075334 | AI40: =K40-L40 -> -0.25981513 | AJ40: =N40-O40 -> -5.1711987 | AK40: =Q40-R40 -> -9.1915724 | AL40: =T40-U40 -> -10.647699 | AM40: =W40-X40 -> 4.4011609 | AN40: =IF(AF40<-2,C40,IF(AE40<-2,C40,"")) -> BI-RUI-006LD | AO40: =IF(AM40<-2,C40,IF(AL40<-2,C40,"")) -> BI-RUI-006LD | AP40: BI-RUI-C022LD | AS40: BI-RUI-C011LD | AV40: BI-RUI-C010LD
...

Sheet AnálisiABI
H1: Value | BC1: 58 | BF1: 53
H2: Monday | K2: Tuesday | N2: Wednesday | Q2: Thursday | T2: Friday | W2: Saturday | Z2: Sunday | AD2: Año completo | AF2: Lunes | AG2: Martes | AH2: Miércoles | AI2: Jueves | AJ2: Viernes | AK2: Sábado | AL2: Domingo | AM2: Lunes | AN2: Martes | AO2: Miércoles | AP2: Jueves | AQ2: Viernes | AR2: Sábado | AS2: Domingo | AT2: Lunes | AU2: Martes | AV2: Miércoles | AW2: Jueves | AX2: Viernes | AY2: Sábado | AZ2: Domingo | BC2: Sonometros | BF2: Sonometros
B3: Mes | C3: Tag | E3: Ld | F3: Le | G3: Ln | H3: dia | I3: tarde | J3: noche | K3: dia | L3: tarde | M3: noche | N3: dia | O3: tarde | P3: noche | Q3: dia | R3: tarde | S3: noche | T3: dia | U3: tarde | V3: noche | W3: dia | X3: tarde | Y3: noche | Z3: dia | AA3: tarde | AB3: noche | AC3: Ld-Ln | AD3: Ld-Le | AE3: Le-Ln | AF3: Ld-Ln | AG3: Ld-Ln | AH3: Ld-Ln | AI3: Ld-Ln | AJ3: Ld-Ln | AK3: Ld-Ln | AL3: Ld-Ln | AM3: Ld-Le | AN3: Ld-Le | AO3: Ld-Le | AP3: Ld-Le | AQ3: Ld-Le | AR3: Ld-Le | AS3: Ld-Le | AT3: Le-Ln | AU3: Le-Ln | AV3: Le-Ln | AW3: Le-Ln | AX3: Le-Ln | AY3: Le-Ln | AZ3: Le-Ln | BA3: Sonómetros con Perfil noche | BB3: Sonómetros con Perfil tarde | BC3: Perfil Noche | BF3: Perfil Tarde | BI3: Total Red
A4: 187 | B4: enero | C4: BI-RUI-001LD | D4: Rgez. Arias | E4: =10*LOG((1/7)*(10^(H4/10)+10^(K4/10)+10^(N4/10)+10^(Q4/10)+10^(T4/10)+10^(W4/10)+10^(Z4/10))) -> 64.175887 | F4: =10*LOG((1/7)*(10^(I4/10)+10^(L4/10)+10^(O4/10)+10^(R4/10)+10^(U4/10)+10^(X4/10)+10^(AA4/10))) -> 62.07926 | G4: =10*LOG((1/7)*(10^(J4/10)+10^(M4/10)+10^(P4/10)+10^(S4/10)+10^(V4/10)+10^(Y4/10)+10^(AB4/10))) -> 67.277129 | H4: 62.658795 | I4: 62.476106 | J4: 60.494662 | K4: 62.935587 | L4: 60.60414 | M4: 62.766541 | N4: 66.611396 | O4: 62.119917 | P4: 67.73573 | Q4: 62.907461 | R4: 62.004881 | S4: 61.88153 | T4: 66.467463 | U4: 63.06384 | V4: 68.529278 | W4: 62.893726 | X4: 62.271837 | Y4: 70.64724 | Z4: 61.994614 | AA4: 61.622052 | AB4: 69.121966 | AC4: =E4-G4 -> -3.1012418 | AD4: =E4-F4 -> 2.0966274 | AE4: =F4-G4 -> -5.1978693 | AF4: =H4-J4 -> 2.164133 | AG4: =K4-M4 -> 0.16904626 | AH4: =N4-P4 -> -1.1243341 | AI4: =Q4-S4 -> 1.025931 | AJ4: =T4-V4 -> -2.0618157 | AK4: =W4-Y4 -> -7.7535144 | AL4: =Z4-AB4 -> -7.1273529 | AM4: =H4-I4 -> 0.18268929 | AN4: =I4-J4 -> 1.9814437 | AO4: =N4-O4 -> 4.4914786 | AP4: =Q4-R4 -> 0.9025799 | AQ4: =T4-U4 -> 3.403623 | AR4: =W4-X4 -> 0.62188902 | AS4: =Z4-AA4 -> 0.37256116 | AT4: =I4-J4 -> 1.9814437 | AU4: =L4-M4 -> -2.1624011 | AV4: =O4-P4 -> -5.6158128 | AW4: =R4-S4 -> 0.12335111 | AX4: =U4-V4 -> -5.4654387 | AY4: =X4-Y4 -> -8.3754035 | AZ4: =AA4-AB4 -> -7.4999141 | BA4: =IF(AB4>55,IF(AL4<2,C4,IF(Y4>55,IF(AK4<2,C4,IF(V4>55,IF(AJ4<2,C4,"")))))) -> BI-RUI-001LD | BB4: =IF(AA4>65,IF(AS4<2,C4,IF(X4>65,IF(AR4<2,C4,IF(U4>65,IF(AQ4<2,C4,"")))))) -> FALSE | BC4: {=_xlfn.UNIQUE(BA4:BA821)} -> #VALUE!
A5: 250 | B5: febrero | C5: BI-RUI-001LD | E5: =10*LOG((1/7)*(10^(H5/10)+10^(K5/10)+10^(N5/10)+10^(Q5/10)+10^(T5/10)+10^(W5/10)+10^(Z5/10))) -> 64.044978 | F5: =10*LOG((1/7)*(10^(I5/10)+10^(L5/10)+10^(O5/10)+10^(R5/10)+10^(U5/10)+10^(X5/10)+10^(AA5/10))) -> 61.230562 | G5: =10*LOG((1/7)*(10^(J5/10)+10^(M5/10)+10^(P5/10)+10^(S5/10)+10^(V5/10)+10^(Y5/10)+10^(AB5/10))) -> 66.245039 | H5: 63.347523 | I5: 59.768522 | J5: 59.805261 | K5: 64.505799 | L5: 62.675691 | M5: 60.824725 | N5: 63.481903 | O5: 60.467503 | P5: 62.059144 | Q5: 63.733194 | R5: 61.346972 | S5: 61.365897 | T5: 66.231968 | U5: 63.272475 | V5: 68.484382 | W5: 63.21594 | X5: 60.59231 | Y5: 70.470423 | Z5: 62.77499 | AA5: 58.723377 | AB5: 67.885564 | AC5: =E5-G5 -> -2.2000612 | AD5: =E5-F5 -> 2.8144156 | AE5: =F5-G5 -> -5.0144769 | AF5: =H5-J5 -> 3.542262 | AG5: =K5-M5 -> 3.6810739 | AH5: =N5-P5 -> 1.4227596 | AI5: =Q5-S5 -> 2.3672965 | AJ5: =T5-V5 -> -2.2524137 | AK5: =W5-Y5 -> -7.254483 | AL5: =Z5-AB5 -> -5.1105732 | AM5: =H5-I5 -> 3.5790011 | AN5: =I5-J5 -> -0.036739171 | AO5: =N5-O5 -> 3.0143999 | AP5: =Q5-R5 -> 2.3862219 | AQ5: =T5-U5 -> 2.9594932 | AR5: =W5-X5 -> 2.6236301 | AS5: =Z5-AA5 -> 4.051613 | AT5: =I5-J5 -> -0.036739171 | AU5: =L5-M5 -> 1.8509654 | AV5: =O5-P5 -> -1.5916403 | AW5: =R5-S5 -> -0.018925448 | AX5: =U5-V5 -> -5.2119069 | AY5: =X5-Y5 -> -9.8781131 | AZ5: =AA5-AB5 -> -9.1621862 | BA5: =IF(AB5>55,IF(AL5<2,C5,IF(Y5>55,IF(AK5<2,C5,IF(V5>55,IF(AJ5<2,C5,"")))))) -> BI-RUI-001LD | BB5: =IF(AA5>65,IF(AS5<2,C5,IF(X5>65,IF(AR5<2,C5,IF(U5>65,IF(AQ5<2,C5,"")))))) -> FALSE | BC5: {=_xlfn.UNIQUE(BA5:BA822)} -> #VALUE! | BD5: 44 sonómetros | BF5: {=_xlfn.UNIQUE(BB4:BB821)} -> FALSE | BI5: {=_xlfn.UNIQUE(C4:C821)} -> BI-RUI-001LD
A6: 438 | B6: marzo | C6: BI-RUI-001LD | E6: =10*LOG((1/7)*(10^(H6/10)+10^(K6/10)+10^(N6/10)+10^(Q6/10)+10^(T6/10)+10^(W6/10)+10^(Z6/10))) -> 64.260378 | F6: =10*LOG((1/7)*(10^(I6/10)+10^(L6/10)+10^(O6/10)+10^(R6/10)+10^(U6/10)+10^(X6/10)+10^(AA6/10))) -> 62.009329 | G6: =10*LOG((1/7)*(10^(J6/10)+10^(M6/10)+10^(P6/10)+10^(S6/10)+10^(V6/10)+10^(Y6/10)+10^(AB6/10))) -> 66.941752 | H6: 64.627038 | I6: 60.730735 | J6: 60.852731 | K6: 64.157622 | L6: 61.184763 | M6: 61.734293 | N6: 65.110056 | O6: 60.831295 | P6: 60.881975 | Q6: 63.813905 | R6: 61.203351 | S6: 61.576753 | T6: 66.334472 | U6: 62.720985 | V6: 69.215179 | W6: 62.326535 | X6: 62.392355 | Y6: 70.790639 | Z6: 61.773812 | AA6: 63.953514 | AB6: 69.494636 | AC6: =E6-G6 -> -2.6813737 | AD6: =E6-F6 -> 2.2510491 | AE6: =F6-G6 -> -4.9324228 | AF6: =H6-J6 -> 3.774307 | AG6: =K6-M6 -> 2.4233286 | AH6: =N6-P6 -> 4.2280804 | AI6: =Q6-S6 -> 2.2371518 | AJ6: =T6-V6 -> -2.880707 | AK6: =W6-Y6 -> -8.4641045 | AL6: =Z6-AB6 -> -7.7208234 | AM6: =H6-I6 -> 3.8963025 | AN6: =I6-J6 -> -0.12199552 | AO6: =N6-O6 -> 4.2787609 | AP6: =Q6-R6 -> 2.6105535 | AQ6: =T6-U6 -> 3.6134868 | AR6: =W6-X6 -> -0.065820134 | AS6: =Z6-AA6 -> -2.1797019 | AT6: =I6-J6 -> -0.12199552 | AU6: =L6-M6 -> -0.54953036 | AV6: =O6-P6 -> -0.050680474 | AW6: =R6-S6 -> -0.37340174 | AX6: =U6-V6 -> -6.4941939 | AY6: =X6-Y6 -> -8.3982844 | AZ6: =AA6-AB6 -> -5.5411215 | BA6: =IF(AB6>55,IF(AL6<2,C6,IF(Y6>55,IF(AK6<2,C6,IF(V6>55,IF(AJ6<2,C6,"")))))) -> BI-RUI-001LD | BB6: =IF(AA6>65,IF(AS6<2,C6,IF(X6>65,IF(AR6<2,C6,IF(U6>65,IF(AQ6<2,C6,"")))))) -> FALSE | BC6: {=_xlfn.UNIQUE(BA6:BA823)} -> #VALUE! | BF6: 0 | BI6: BI-RUI-004LD
A7: 0 | B7: abril | C7: BI-RUI-001LD | E7: =10*LOG((1/7)*(10^(H7/10)+10^(K7/10)+10^(N7/10)+10^(Q7/10)+10^(T7/10)+10^(W7/10)+10^(Z7/10))) -> 63.079782 | F7: =10*LOG((1/7)*(10^(I7/10)+10^(L7/10)+10^(O7/10)+10^(R7/10)+10^(U7/10)+10^(X7/10)+10^(AA7/10))) -> 64.793207 | G7: =10*LOG((1/7)*(10^(J7/10)+10^(M7/10)+10^(P7/10)+10^(S7/10)+10^(V7/10)+10^(Y7/10)+10^(AB7/10))) -> 67.446113 | H7: 61.580151 | I7: 60.443165 | J7: 59.517598 | K7: 63.287053 | L7: 70.515742 | M7: 63.670796 | N7: 63.609378 | O7: 62.114813 | P7: 68.190563 | Q7: 61.978456 | R7: 63.970992 | S7: 62.901147 | T7: 64.228229 | U7: 61.16625 | V7: 69.298418 | W7: 63.132935 | X7: 63.961765 | Y7: 70.498133 | Z7: 63.17597 | AA7: 59.126623 | AB7: 68.685567 | AC7: =E7-G7 -> -4.3663313 | AD7: =E7-F7 -> -1.7134252 | AE7: =F7-G7 -> -2.6529061 | AF7: =H7-J7 -> 2.0625525 | AG7: =K7-M7 -> -0.38374373 | AH7: =N7-P7 -> -4.5811849 | AI7: =Q7-S7 -> -0.92269058 | AJ7: =T7-V7 -> -5.0701892 | AK7: =W7-Y7 -> -7.3651975 | AL7: =Z7-AB7 -> -5.5095966 | AM7: =H7-I7 -> 1.1369857 | AN7: =I7-J7 -> 0.92556677 | AO7: =N7-O7 -> 1.4945659 | AP7: =Q7-R7 -> -1.9925351 | AQ7: =T7-U7 -> 3.0619791 | AR7: =W7-X7 -> -0.82883031 | AS7: =Z7-AA7 -> 4.049347 | AT7: =I7-J7 -> 0.92556677 | AU7: =L7-M7 -> 6.8449457 | AV7: =O7-P7 -> -6.0757508 | AW7: =R7-S7 -> 1.0698445 | AX7: =U7-V7 -> -8.1321682 | AY7: =X7-Y7 -> -6.5363672 | AZ7: =AA7-AB7 -> -9.5589435 | BA7: =IF(AB7>55,IF(AL7<2,C7,IF(Y7>55,IF(AK7<2,C7,IF(V7>55,IF(AJ7<2,C7,"")))))) -> BI-RUI-001LD | BB7: =IF(AA7>65,IF(AS7<2,C7,IF(X7>65,IF(AR7<2,C7,IF(U7>65,IF(AQ7<2,C7,"")))))) -> FALSE | BC7: {=_xlfn.UNIQUE(BA7:BA824)} -> #VALUE! | BF7: BI-RUI-004LD | BI7: BI-RUI-005LD
A8: 501 | B8: mayo | C8: BI-RUI-001LD | E8: =10*LOG((1/7)*(10^(H8/10)+10^(K8/10)+10^(N8/10)+10^(Q8/10)+10^(T8/10)+10^(W8/10)+10^(Z8/10))) -> 63.633475 | F8: =10*LOG((1/7)*(10^(I8/10)+10^(L8/10)+10^(O8/10)+10^(R8/10)+10^(U8/10)+10^(X8/10)+10^(AA8/10))) -> 62.129722 | G8: =10*LOG((1/7)*(10^(J8/10)+10^(M8/10)+10^(P8/10)+10^(S8/10)+10^(V8/10)+10^(Y8/10)+10^(AB8/10))) -> 67.129593 | H8: 63.523597 | I8: 59.978862 | J8: 63.361538 | K8: 62.902213 | L8: 60.726175 | M8: 59.719009 | N8: 62.282605 | O8: 61.122283 | P8: 60.654664 | Q8: 62.659114 | R8: 64.861398 | S8: 61.488208 | T8: 66.479412 | U8: 62.672438 | V8: 70.321195 | W8: 63.180426 | X8: 62.738659 | Y8: 70.650322 | Z8: 62.779969 | AA8: 60.669288 | AB8: 69.077105 | AC8: =E8-G8 -> -3.4961179 | AD8: =E8-F8 -> 1.5037526 | AE8: =F8-G8 -> -4.9998705 | AF8: =H8-J8 -> 0.16205927 | AG8: =K8-M8 -> 3.1832043 | AH8: =N8-P8 -> 1.6279401 | AI8: =Q8-S8 -> 1.1709056 | AJ8: =T8-V8 -> -3.8417837 | AK8: =W8-Y8 -> -7.4698963 | AL8: =Z8-AB8 -> -6.2971355 | AM8: =H8-I8 -> 3.5447354 | AN8: =I8-J8 -> -3.3826762 | AO8: =N8-O8 -> 1.160322 | AP8: =Q8-R8 -> -2.2022843 | AQ8: =T8-U8 -> 3.8069734 | AR8: =W8-X8 -> 0.4417673 | AS8: =Z8-AA8 -> 2.1106813 | AT8: =I8-J8 -> -3.3826762 | AU8: =L8-M8 -> 1.0071658 | AV8: =O8-P8 -> 0.46761812 | AW8: =R8-S8 -> 3.37319 | AX8: =U8-V8 -> -7.6487571 | AY8: =X8-Y8 -> -7.9116636 | AZ8: =AA8-AB8 -> -8.4078168 | BA8: =IF(AB8>55,IF(AL8<2,C8,IF(Y8>55,IF(AK8<2,C8,IF(V8>55,IF(AJ8<2,C8,"")))))) -> BI-RUI-001LD | BB8: =IF(AA8>65,IF(AS8<2,C8,IF(X8>65,IF(AR8<2,C8,IF(U8>65,IF(AQ8<2,C8,"")))))) -> FALSE | BC8: {=_xlfn.UNIQUE(BA8:BA825)} -> #VALUE! | BF8: BI-RUI-005LD | BI8: BI-RUI-006LD
A9: 375 | B9: junio | C9: BI-RUI-001LD | E9: =10*LOG((1/7)*(10^(H9/10)+10^(K9/10)+10^(N9/10)+10^(Q9/10)+10^(T9/10)+10^(W9/10)+10^(Z9/10))) -> 64.548058 | F9: =10*LOG((1/7)*(10^(I9/10)+10^(L9/10)+10^(O9/10)+10^(R9/10)+10^(U9/10)+10^(X9/10)+10^(AA9/10))) -> 64.000619 | G9: =10*LOG((1/7)*(10^(J9/10)+10^(M9/10)+10^(P9/10)+10^(S9/10)+10^(V9/10)+10^(Y9/10)+10^(AB9/10))) -> 67.391779 | H9: 65.743959 | I9: 61.661502 | J9: 66.184326 | K9: 64.19926 | L9: 63.322566 | M9: 61.107384 | N9: 63.853472 | O9: 61.941887 | P9: 61.623738 | Q9: 63.339182 | R9: 68.224253 | S9: 63.42851 | T9: 66.31593 | U9: 63.590634 | V9: 69.919741 | W9: 62.938087 | X9: 63.432547 | Y9: 71.080977 | Z9: 64.362993 | AA9: 61.047069 | AB9: 68.229767 | AC9: =E9-G9 -> -2.8437202 | AD9: =E9-F9 -> 0.54743968 | AE9: =F9-G9 -> -3.3911599 | AF9: =H9-J9 -> -0.4403675 | AG9: =K9-M9 -> 3.091876 | AH9: =N9-P9 -> 2.2297341 | AI9: =Q9-S9 -> -0.089328442 | AJ9: =T9-V9 -> -3.6038106 | AK9: =W9-Y9 -> -8.1428901 | AL9: =Z9-AB9 -> -3.8667738 | AM9: =H9-I9 -> 4.0824571 | AN9: =I9-J9 -> -4.5228246 | AO9: =N9-O9 -> 1.9115847 | AP9: =Q9-R9 -> -4.8850712 | AQ9: =T9-U9 -> 2.7252963 | AR9: =W9-X9 -> -0.49446006 | AS9: =Z9-AA9 -> 3.3159243 | AT9: =I9-J9 -> -4.5228246 | AU9: =L9-M9 -> 2.2151827 | AV9: =O9-P9 -> 0.31814935 | AW9: =R9-S9 -> 4.7957427 | AX9: =U9-V9 -> -6.3291068 | AY9: =X9-Y9 -> -7.6484301 | AZ9: =AA9-AB9 -> -7.1826981 | BA9: =IF(AB9>55,IF(AL9<2,C9,IF(Y9>55,IF(AK9<2,C9,IF(V9>55,IF(AJ9<2,C9,"")))))) -> BI-RUI-001LD | BB9: =IF(AA9>65,IF(AS9<2,C9,IF(X9>65,IF(AR9<2,C9,IF(U9>65,IF(AQ9<2,C9,"")))))) -> FALSE | BC9: {=_xlfn.UNIQUE(BA9:BA826)} -> #VALUE! | BF9: BI-RUI-006LD | BI9: BI-RUI-007LD
A10: 312 | B10: julio | C10: BI-RUI-001LD | E10: =10*LOG((1/7)*(10^(H10/10)+10^(K10/10)+10^(N10/10)+10^(Q10/10)+10^(T10/10)+10^(W10/10)+10^(Z10/10))) -> 63.146692 | F10: =10*LOG((1/7)*(10^(I10/10)+10^(L10/10)+10^(O10/10)+10^(R10/10)+10^(U10/10)+10^(X10/10)+10^(AA10/10))) -> 62.065792 | G10: =10*LOG((1/7)*(10^(J10/10)+10^(M10/10)+10^(P10/10)+10^(S10/10)+10^(V10/10)+10^(Y10/10)+10^(AB10/10))) -> 62.581616 | H10: 63.040529 | I10: 60.750734 | J10: 61.745717 | K10: 62.157049 | L10: 61.731882 | M10: 62.849265 | N10: 63.722154 | O10: 62.30274 | P10: 60.092869 | Q10: 64.201856 | R10: 63.345898 | S10: 62.448215 | T10: 64.821695 | U10: 63.262095 | V10: 65.334879 | W10: 61.951915 | X10: 60.85273 | Y10: 63.221484 | Z10: 60.789284 | AA10: 61.425659 | AB10: 59.85832 | AC10: =E10-G10 -> 0.56507581 | AD10: =E10-F10 -> 1.0809005 | AE10: =F10-G10 -> -0.51582469 | AF10: =H10-J10 -> 1.2948111 | AG10: =K10-M10 -> -0.69221583 | AH10: =N10-P10 -> 3.6292846 | AI10: =Q10-S10 -> 1.7536412 | AJ10: =T10-V10 -> -0.51318451 | AK10: =W10-Y10 -> -1.2695687 | AL10: =Z10-AB10 -> 0.93096422 | AM10: =H10-I10 -> 2.2897944 | AN10: =I10-J10 -> -0.99498336 | AO10: =N10-O10 -> 1.4194141 | AP10: =Q10-R10 -> 0.85595862 | AQ10: =T10-U10 -> 1.5596001 | AR10: =W10-X10 -> 1.0991852 | AS10: =Z10-AA10 -> -0.63637505 | AT10: =I10-J10 -> -0.99498336 | AU10: =L10-M10 -> -1.1173834 | AV10: =O10-P10 -> 2.2098706 | AW10: =R10-S10 -> 0.89768254 | AX10: =U10-V10 -> -2.0727846 | AY10: =X10-Y10 -> -2.3687539 | AZ10: =AA10-AB10 -> 1.5673393 | BA10: =IF(AB10>55,IF(AL10<2,C10,IF(Y10>55,IF(AK10<2,C10,IF(V10>55,IF(AJ10<2,C10,"")))))) -> BI-RUI-001LD | BB10: =IF(AA10>65,IF(AS10<2,C10,IF(X10>65,IF(AR10<2,C10,IF(U10>65,IF(AQ10<2,C10,"")))))) -> FALSE | BC10: {=_xlfn.UNIQUE(BA10:BA827)} -> #VALUE! | BF10: BI-RUI-007LD | BI10: BI-RUI-008LD
A11: 63 | B11: agosto | C11: BI-RUI-001LD | E11: =10*LOG((1/7)*(10^(H11/10)+10^(K11/10)+10^(N11/10)+10^(Q11/10)+10^(T11/10)+10^(W11/10)+10^(Z11/10))) -> 62.677231 | F11: =10*LOG((1/7)*(10^(I11/10)+10^(L11/10)+10^(O11/10)+10^(R11/10)+10^(U11/10)+10^(X11/10)+10^(AA11/10))) -> 62.978838 | G11: =10*LOG((1/7)*(10^(J11/10)+10^(M11/10)+10^(P11/10)+10^(S11/10)+10^(V11/10)+10^(Y11/10)+10^(AB11/10))) -> 60.99973 | H11: 62.745425 | I11: 61.710984 | J11: 60.100114 | K11: 62.882507 | L11: 60.861708 | M11: 61.328807 | N11: 63.262384 | O11: 60.989646 | P11: 61.528371 | Q11: 64.063435 | R11: 62.623344 | S11: 60.678892 | T11: 62.87886 | U11: 61.596343 | V11: 60.790567 | W11: 61.584777 | X11: 66.219949 | Y11: 60.719522 | Z11: 60.388788 | AA11: 63.942898 | AB11: 61.643012 | AC11: =E11-G11 -> 1.6775014 | AD11: =E11-F11 -> -0.3016066 | AE11: =F11-G11 -> 1.979108 | AF11: =H11-J11 -> 2.645311 | AG11: =K11-M11 -> 1.5536999 | AH11: =N11-P11 -> 1.7340133 | AI11: =Q11-S11 -> 3.3845426 | AJ11: =T11-V11 -> 2.0882939 | AK11: =W11-Y11 -> 0.86525573 | AL11: =Z11-AB11 -> -1.2542245 | AM11: =H11-I11 -> 1.0344408 | AN11: =I11-J11 -> 1.6108703 | AO11: =N11-O11 -> 2.2727375 | AP11: =Q11-R11 -> 1.4400907 | AQ11: =T11-U11 -> 1.2825178 | AR11: =W11-X11 -> -4.6351713 | AS11: =Z11-AA11 -> -3.5541101 | AT11: =I11-J11 -> 1.6108703 | AU11: =L11-M11 -> -0.46709893 | AV11: =O11-P11 -> -0.5387242 | AW11: =R11-S11 -> 1.9444519 | AX11: =U11-V11 -> 0.80577611 | AY11: =X11-Y11 -> 5.5004271 | AZ11: =AA11-AB11 -> 2.2998856 | BA11: =IF(AB11>55,IF(AL11<2,C11,IF(Y11>55,IF(AK11<2,C11,IF(V11>55,IF(AJ11<2,C11,"")))))) -> BI-RUI-001LD | BB11: =IF(AA11>65,IF(AS11<2,C11,IF(X11>65,IF(AR11<2,C11,IF(U11>65,IF(AQ11<2,C11,"")))))) -> FALSE | BC11: {=_xlfn.UNIQUE(BA11:BA828)} -> BI-RUI-001LD | BF11: BI-RUI-008LD | BI11: BI-RUI-009LD
A12: 687 | B12: septiembre | C12: BI-RUI-001LD | E12: =10*LOG((1/7)*(10^(H12/10)+10^(K12/10)+10^(N12/10)+10^(Q12/10)+10^(T12/10)+10^(W12/10)+10^(Z12/10))) -> 63.550204 | F12: =10*LOG((1/7)*(10^(I12/10)+10^(L12/10)+10^(O12/10)+10^(R12/10)+10^(U12/10)+10^(X12/10)+10^(AA12/10))) -> 62.034386 | G12: =10*LOG((1/7)*(10^(J12/10)+10^(M12/10)+10^(P12/10)+10^(S12/10)+10^(V12/10)+10^(Y12/10)+10^(AB12/10))) -> 65.902127 | H12: 63.540125 | I12: 61.130769 | J12: 62.599697 | K12: 62.593602 | L12: 60.915162 | M12: 62.226171 | N12: 63.165486 | O12: 61.198379 | P12: 58.857458 | Q12: 64.201542 | R12: 62.841555 | S12: 68.552497 | T12: 66.437555 | U12: 63.862222 | V12: 67.876653 | W12: 61.013411 | X12: 61.138157 | Y12: 67.882189 | Z12: 61.48258 | AA12: 62.242349 | AB12: 65.501635 | AC12: =E12-G12 -> -2.3519231 | AD12: =E12-F12 -> 1.5158178 | AE12: =F12-G12 -> -3.8677409 | AF12: =H12-J12 -> 0.94042773 | AG12: =K12-M12 -> 0.36743066 | AH12: =N12-P12 -> 4.3080278 | AI12: =Q12-S12 -> -4.3509545 | AJ12: =T12-V12 -> -1.4390978 | AK12: =W12-Y12 -> -6.8687782 | AL12: =Z12-AB12 -> -4.0190549 | AM12: =H12-I12 -> 2.4093559 | AN12: =I12-J12 -> -1.4689281 | AO12: =N12-O12 -> 1.967107 | AP12: =Q12-R12 -> 1.3599868 | AQ12: =T12-U12 -> 2.575333 | AR12: =W12-X12 -> -0.12474605 | AS12: =Z12-AA12 -> -0.75976927 | AT12: =I12-J12 -> -1.4689281 | AU12: =L12-M12 -> -1.3110091 | AV12: =O12-P12 -> 2.3409209 | AW12: =R12-S12 -> -5.7109413 | AX12: =U12-V12 -> -4.0144308 | AY12: =X12-Y12 -> -6.7440321 | AZ12: =AA12-AB12 -> -3.2592856 | BA12: =IF(AB12>55,IF(AL12<2,C12,IF(Y12>55,IF(AK12<2,C12,IF(V12>55,IF(AJ12<2,C12,"")))))) -> BI-RUI-001LD | BB12: =IF(AA12>65,IF(AS12<2,C12,IF(X12>65,IF(AR12<2,C12,IF(U12>65,IF(AQ12<2,C12,"")))))) -> FALSE | BC12: 0 | BF12: BI-RUI-009LD | BI12: BI-RUI-010LD
A13: 625 | B13: octubre | C13: BI-RUI-001LD | E13: =10*LOG((1/7)*(10^(H13/10)+10^(K13/10)+10^(N13/10)+10^(Q13/10)+10^(T13/10)+10^(W13/10)+10^(Z13/10))) -> 64.40565 | F13: =10*LOG((1/7)*(10^(I13/10)+10^(L13/10)+10^(O13/10)+10^(R13/10)+10^(U13/10)+10^(X13/10)+10^(AA13/10))) -> 62.445015 | G13: =10*LOG((1/7)*(10^(J13/10)+10^(M13/10)+10^(P13/10)+10^(S13/10)+10^(V13/10)+10^(Y13/10)+10^(AB13/10))) -> 67.980382 | H13: 62.497209 | I13: 61.921207 | J13: 60.798772 | K13: 64.093417 | L13: 61.342728 | M13: 60.931889 | N13: 65.287561 | O13: 60.559798 | P13: 67.547626 | Q13: 65.066084 | R13: 61.011945 | S13: 66.968411 | T13: 66.847043 | U13: 63.281344 | V13: 69.488448 | W13: 62.39244 | X13: 65.916641 | Y13: 70.98869 | Z13: 62.548712 | AA13: 59.724336 | AB13: 69.740683 | AC13: =E13-G13 -> -3.5747326 | AD13: =E13-F13 -> 1.9606347 | AE13: =F13-G13 -> -5.5353673 | AF13: =H13-J13 -> 1.6984368 | AG13: =K13-M13 -> 3.1615286 | AH13: =N13-P13 -> -2.2600648 | AI13: =Q13-S13 -> -1.9023273 | AJ13: =T13-V13 -> -2.6414052 | AK13: =W13-Y13 -> -8.5962499 | AL13: =Z13-AB13 -> -7.1919716 | AM13: =H13-I13 -> 0.57600214 | AN13: =I13-J13 -> 1.1224347 | AO13: =N13-O13 -> 4.7277633 | AP13: =Q13-R13 -> 4.0541387 | AQ13: =T13-U13 -> 3.5656991 | AR13: =W13-X13 -> -3.5242005 | AS13: =Z13-AA13 -> 2.8243755 | AT13: =I13-J13 -> 1.1224347 | AU13: =L13-M13 -> 0.41083951 | AV13: =O13-P13 -> -6.9878281 | AW13: =R13-S13 -> -5.956466 | AX13: =U13-V13 -> -6.2071043 | AY13: =X13-Y13 -> -5.0720493 | AZ13: =AA13-AB13 -> -10.016347 | BA13: =IF(AB13>55,IF(AL13<2,C13,IF(Y13>55,IF(AK13<2,C13,IF(V13>55,IF(AJ13<2,C13,"")))))) -> BI-RUI-001LD | BB13: =IF(AA13>65,IF(AS13<2,C13,IF(X13>65,IF(AR13<2,C13,IF(U13>65,IF(AQ13<2,C13,"")))))) -> FALSE | BC13: BI-RUI-004LD | BF13: BI-RUI-010LD | BI13: BI-RUI-011LD
A14: 564 | B14: noviembre | C14: BI-RUI-001LD | E14: =10*LOG((1/7)*(10^(H14/10)+10^(K14/10)+10^(N14/10)+10^(Q14/10)+10^(T14/10)+10^(W14/10)+10^(Z14/10))) -> 63.848103 | F14: =10*LOG((1/7)*(10^(I14/10)+10^(L14/10)+10^(O14/10)+10^(R14/10)+10^(U14/10)+10^(X14/10)+10^(AA14/10))) -> 61.960563 | G14: =10*LOG((1/7)*(10^(J14/10)+10^(M14/10)+10^(P14/10)+10^(S14/10)+10^(V14/10)+10^(Y14/10)+10^(AB14/10))) -> 66.477427 | H14: 64.093063 | I14: 61.045177 | J14: 60.523574 | K14: 63.690975 | L14: 63.082605 | M14: 61.459496 | N14: 62.313455 | O14: 61.303862 | P14: 61.562084 | Q14: 63.248242 | R14: 61.249189 | S14: 62.783463 | T14: 66.29722 | U14: 62.54308 | V14: 68.473099 | W14: 63.156178 | X14: 63.669228 | Y14: 70.28848 | Z14: 62.845805 | AA14: 59.450646 | AB14: 68.76481 | AC14: =E14-G14 -> -2.6293237 | AD14: =E14-F14 -> 1.8875396 | AE14: =F14-G14 -> -4.5168633 | AF14: =H14-J14 -> 3.5694889 | AG14: =K14-M14 -> 2.2314794 | AH14: =N14-P14 -> 0.75137153 | AI14: =Q14-S14 -> 0.46477837 | AJ14: =T14-V14 -> -2.1758788 | AK14: =W14-Y14 -> -7.1323015 | AL14: =Z14-AB14 -> -5.919005 | AM14: =H14-I14 -> 3.0478855 | AN14: =I14-J14 -> 0.52160342 | AO14: =N14-O14 -> 1.0095936 | AP14: =Q14-R14 -> 1.999053 | AQ14: =T14-U14 -> 3.7541405 | AR14: =W14-X14 -> -0.51304995 | AS14: =Z14-AA14 -> 3.3951584 | AT14: =I14-J14 -> 0.52160342 | AU14: =L14-M14 -> 1.6231088 | AV14: =O14-P14 -> -0.25822204 | AW14: =R14-S14 -> -1.5342746 | AX14: =U14-V14 -> -5.9300193 | AY14: =X14-Y14 -> -6.6192516 | AZ14: =AA14-AB14 -> -9.3141634 | BA14: =IF(AB14>55,IF(AL14<2,C14,IF(Y14>55,IF(AK14<2,C14,IF(V14>55,IF(AJ14<2,C14,"")))))) -> BI-RUI-001LD | BB14: =IF(AA14>65,IF(AS14<2,C14,IF(X14>65,IF(AR14<2,C14,IF(U14>65,IF(AQ14<2,C14,"")))))) -> FALSE | BF14: BI-RUI-011LD | BI14: BI-RUI-013LD
A15: 126 | B15: diciembre | C15: BI-RUI-001LD | E15: =10*LOG((1/7)*(10^(H15/10)+10^(K15/10)+10^(N15/10)+10^(Q15/10)+10^(T15/10)+10^(W15/10)+10^(Z15/10))) -> 64.3755 | F15: =10*LOG((1/7)*(10^(I15/10)+10^(L15/10)+10^(O15/10)+10^(R15/10)+10^(U15/10)+10^(X15/10)+10^(AA15/10))) -> 61.715579 | G15: =10*LOG((1/7)*(10^(J15/10)+10^(M15/10)+10^(P15/10)+10^(S15/10)+10^(V15/10)+10^(Y15/10)+10^(AB15/10))) -> 68.412977 | H15: 63.684734 | I15: 62.7847 | J15: 65.70116 | K15: 64.827418 | L15: 61.422633 | M15: 66.827531 | N15: 66.494323 | O15: 61.346406 | P15: 68.002551 | Q15: 63.464968 | R15: 61.292407 | S15: 67.703661 | T15: 65.882814 | U15: 62.698584 | V15: 70.079862 | W15: 62.540571 | X15: 61.552031 | Y15: 70.396716 | Z15: 61.596487 | AA15: 60.427748 | AB15: 68.25507 | AC15: =E15-G15 -> -4.0374776 | AD15: =E15-F15 -> 2.6599211 | AE15: =F15-G15 -> -6.6973988 | AF15: =H15-J15 -> -2.0164265 | AG15: =K15-M15 -> -2.0001128 | AH15: =N15-P15 -> -1.5082284 | AI15: =Q15-S15 -> -4.2386925 | AJ15: =T15-V15 -> -4.1970482 | AK15: =W15-Y15 -> -7.8561445 | AL15: =Z15-AB15 -> -6.6585824 | AM15: =H15-I15 -> 0.90003407 | AN15: =I15-J15 -> -2.9164606 | AO15: =N15-O15 -> 5.1479166 | AP15: =Q15-R15 -> 2.1725616 | AQ15: =T15-U15 -> 3.1842299 | AR15: =W15-X15 -> 0.98854074 | AS15: =Z15-AA15 -> 1.1687397 | AT15: =I15-J15 -> -2.9164606 | AU15: =L15-M15 -> -5.4048976 | AV15: =O15-P15 -> -6.656145 | AW15: =R15-S15 -> -6.4112541 | AX15: =U15-V15 -> -7.3812781 | AY15: =X15-Y15 -> -8.8446852 | AZ15: =AA15-AB15 -> -7.8273221 | BA15: =IF(AB15>55,IF(AL15<2,C15,IF(Y15>55,IF(AK15<2,C15,IF(V15>55,IF(AJ15<2,C15,"")))))) -> BI-RUI-001LD | BB15: =IF(AA15>65,IF(AS15<2,C15,IF(X15>65,IF(AR15<2,C15,IF(U15>65,IF(AQ15<2,C15,"")))))) -> FALSE | BC15: BI-RUI-005LD | BF15: BI-RUI-013LD | BI15: BI-RUI-015LD
